[2024-04-24T23:25:43.453+0000] {local_task_job_runner.py:120} INFO - ::group::Pre task execution logs
[2024-04-24T23:25:43.471+0000] {taskinstance.py:2073} INFO - Dependencies all met for dep_context=non-requeueable deps ti=<TaskInstance: spotify_extract_dag.el_spotify manual__2024-04-24T23:23:50.101193+00:00 [queued]>
[2024-04-24T23:25:43.476+0000] {taskinstance.py:2073} INFO - Dependencies all met for dep_context=requeueable deps ti=<TaskInstance: spotify_extract_dag.el_spotify manual__2024-04-24T23:23:50.101193+00:00 [queued]>
[2024-04-24T23:25:43.477+0000] {taskinstance.py:2303} INFO - Starting attempt 2 of 4
[2024-04-24T23:25:43.487+0000] {taskinstance.py:2327} INFO - Executing <Task(DockerOperator): el_spotify> on 2024-04-24 23:23:50.101193+00:00
[2024-04-24T23:25:43.493+0000] {warnings.py:110} WARNING - /home/***/.local/lib/python3.12/site-packages/***/task/task_runner/standard_task_runner.py:61: DeprecationWarning: This process (pid=94) is multi-threaded, use of fork() may lead to deadlocks in the child.
  pid = os.fork()

[2024-04-24T23:25:43.494+0000] {standard_task_runner.py:63} INFO - Started process 95 to run task
[2024-04-24T23:25:43.494+0000] {standard_task_runner.py:90} INFO - Running: ['***', 'tasks', 'run', 'spotify_extract_dag', 'el_spotify', 'manual__2024-04-24T23:23:50.101193+00:00', '--job-id', '34', '--raw', '--subdir', 'DAGS_FOLDER/meltano_spotify_dag.py', '--cfg-path', '/tmp/tmprkxx522b']
[2024-04-24T23:25:43.496+0000] {standard_task_runner.py:91} INFO - Job 34: Subtask el_spotify
[2024-04-24T23:25:43.527+0000] {task_command.py:426} INFO - Running <TaskInstance: spotify_extract_dag.el_spotify manual__2024-04-24T23:23:50.101193+00:00 [running]> on host ba7bb483867c
[2024-04-24T23:25:43.590+0000] {taskinstance.py:2644} INFO - Exporting env vars: AIRFLOW_CTX_DAG_OWNER='***' AIRFLOW_CTX_DAG_ID='spotify_extract_dag' AIRFLOW_CTX_TASK_ID='el_spotify' AIRFLOW_CTX_EXECUTION_DATE='2024-04-24T23:23:50.101193+00:00' AIRFLOW_CTX_TRY_NUMBER='2' AIRFLOW_CTX_DAG_RUN_ID='manual__2024-04-24T23:23:50.101193+00:00'
[2024-04-24T23:25:43.590+0000] {taskinstance.py:430} INFO - ::endgroup::
[2024-04-24T23:25:43.610+0000] {docker.py:486} INFO - Pulling docker image meltano
[2024-04-24T23:25:45.578+0000] {taskinstance.py:441} INFO - ::group::Post task execution logs
[2024-04-24T23:25:45.578+0000] {taskinstance.py:2890} ERROR - Task failed with exception
Traceback (most recent call last):
  File "/home/airflow/.local/lib/python3.12/site-packages/docker/api/client.py", line 265, in _raise_for_status
    response.raise_for_status()
  File "/home/airflow/.local/lib/python3.12/site-packages/requests/models.py", line 1021, in raise_for_status
    raise HTTPError(http_error_msg, response=self)
requests.exceptions.HTTPError: 404 Client Error: Not Found for url: http+docker://localhost/v1.43/images/create?tag=latest&fromImage=meltano

The above exception was the direct cause of the following exception:

Traceback (most recent call last):
  File "/home/airflow/.local/lib/python3.12/site-packages/airflow/models/taskinstance.py", line 465, in _execute_task
    result = _execute_callable(context=context, **execute_callable_kwargs)
             ^^^^^^^^^^^^^^^^^^^^^^^^^^^^^^^^^^^^^^^^^^^^^^^^^^^^^^^^^^^^^
  File "/home/airflow/.local/lib/python3.12/site-packages/airflow/models/taskinstance.py", line 432, in _execute_callable
    return execute_callable(context=context, **execute_callable_kwargs)
           ^^^^^^^^^^^^^^^^^^^^^^^^^^^^^^^^^^^^^^^^^^^^^^^^^^^^^^^^^^^^
  File "/home/airflow/.local/lib/python3.12/site-packages/airflow/models/baseoperator.py", line 400, in wrapper
    return func(self, *args, **kwargs)
           ^^^^^^^^^^^^^^^^^^^^^^^^^^^
  File "/home/airflow/.local/lib/python3.12/site-packages/airflow/providers/docker/operators/docker.py", line 488, in execute
    for output in self.cli.pull(self.image, stream=True, decode=True):
                  ^^^^^^^^^^^^^^^^^^^^^^^^^^^^^^^^^^^^^^^^^^^^^^^^^^^
  File "/home/airflow/.local/lib/python3.12/site-packages/docker/api/image.py", line 429, in pull
    self._raise_for_status(response)
  File "/home/airflow/.local/lib/python3.12/site-packages/docker/api/client.py", line 267, in _raise_for_status
    raise create_api_error_from_http_exception(e) from e
          ^^^^^^^^^^^^^^^^^^^^^^^^^^^^^^^^^^^^^^^
  File "/home/airflow/.local/lib/python3.12/site-packages/docker/errors.py", line 39, in create_api_error_from_http_exception
    raise cls(e, response=response, explanation=explanation) from e
docker.errors.ImageNotFound: 404 Client Error for http+docker://localhost/v1.43/images/create?tag=latest&fromImage=meltano: Not Found ("pull access denied for meltano, repository does not exist or may require 'docker login': denied: requested access to the resource is denied")
[2024-04-24T23:25:45.587+0000] {taskinstance.py:1205} INFO - Marking task as UP_FOR_RETRY. dag_id=spotify_extract_dag, task_id=el_spotify, execution_date=20240424T232350, start_date=20240424T232543, end_date=20240424T232545
[2024-04-24T23:25:45.596+0000] {standard_task_runner.py:110} ERROR - Failed to execute job 34 for task el_spotify (404 Client Error for http+docker://localhost/v1.43/images/create?tag=latest&fromImage=meltano: Not Found ("pull access denied for meltano, repository does not exist or may require 'docker login': denied: requested access to the resource is denied"); 95)
[2024-04-24T23:25:45.636+0000] {local_task_job_runner.py:240} INFO - Task exited with return code 1
[2024-04-24T23:25:45.650+0000] {taskinstance.py:3482} INFO - 0 downstream tasks scheduled from follow-on schedule check
[2024-04-24T23:25:45.653+0000] {local_task_job_runner.py:222} INFO - ::endgroup::
