[2024-04-24T23:32:31.557+0000] {local_task_job_runner.py:120} INFO - ::group::Pre task execution logs
[2024-04-24T23:32:31.575+0000] {taskinstance.py:2073} INFO - Dependencies all met for dep_context=non-requeueable deps ti=<TaskInstance: spotify_extract_dag.el_spotify manual__2024-04-24T23:29:09.935982+00:00 [queued]>
[2024-04-24T23:32:31.580+0000] {taskinstance.py:2073} INFO - Dependencies all met for dep_context=requeueable deps ti=<TaskInstance: spotify_extract_dag.el_spotify manual__2024-04-24T23:29:09.935982+00:00 [queued]>
[2024-04-24T23:32:31.581+0000] {taskinstance.py:2303} INFO - Starting attempt 2 of 4
[2024-04-24T23:32:31.591+0000] {taskinstance.py:2327} INFO - Executing <Task(DockerOperator): el_spotify> on 2024-04-24 23:29:09.935982+00:00
[2024-04-24T23:32:31.597+0000] {warnings.py:110} WARNING - /home/***/.local/lib/python3.12/site-packages/***/task/task_runner/standard_task_runner.py:61: DeprecationWarning: This process (pid=193) is multi-threaded, use of fork() may lead to deadlocks in the child.
  pid = os.fork()

[2024-04-24T23:32:31.597+0000] {standard_task_runner.py:63} INFO - Started process 194 to run task
[2024-04-24T23:32:31.598+0000] {standard_task_runner.py:90} INFO - Running: ['***', 'tasks', 'run', 'spotify_extract_dag', 'el_spotify', 'manual__2024-04-24T23:29:09.935982+00:00', '--job-id', '38', '--raw', '--subdir', 'DAGS_FOLDER/meltano_spotify_dag.py', '--cfg-path', '/tmp/tmps2qm6tt2']
[2024-04-24T23:32:31.599+0000] {standard_task_runner.py:91} INFO - Job 38: Subtask el_spotify
[2024-04-24T23:32:31.633+0000] {task_command.py:426} INFO - Running <TaskInstance: spotify_extract_dag.el_spotify manual__2024-04-24T23:29:09.935982+00:00 [running]> on host ba7bb483867c
[2024-04-24T23:32:31.701+0000] {taskinstance.py:2644} INFO - Exporting env vars: AIRFLOW_CTX_DAG_OWNER='***' AIRFLOW_CTX_DAG_ID='spotify_extract_dag' AIRFLOW_CTX_TASK_ID='el_spotify' AIRFLOW_CTX_EXECUTION_DATE='2024-04-24T23:29:09.935982+00:00' AIRFLOW_CTX_TRY_NUMBER='2' AIRFLOW_CTX_DAG_RUN_ID='manual__2024-04-24T23:29:09.935982+00:00'
[2024-04-24T23:32:31.701+0000] {taskinstance.py:430} INFO - ::endgroup::
[2024-04-24T23:32:31.721+0000] {docker.py:359} INFO - Starting docker container from image meltano
[2024-04-24T23:32:31.723+0000] {docker.py:367} WARNING - Using remote engine or docker-in-docker and mounting temporary volume from host is not supported. Falling back to `mount_tmp_dir=False` mode. You can set `mount_tmp_dir` parameter to False to disable mounting and remove the warning
[2024-04-24T23:32:32.578+0000] {docker.py:429} INFO - Usage: meltano [OPTIONS] COMMAND [ARGS]...
Try 'meltano --help' for help.

Error: No such command 'meltano'.

Did you mean one of these?
    elt
[2024-04-24T23:32:32.809+0000] {taskinstance.py:441} INFO - ::group::Post task execution logs
[2024-04-24T23:32:32.817+0000] {taskinstance.py:2890} ERROR - Task failed with exception
Traceback (most recent call last):
  File "/home/airflow/.local/lib/python3.12/site-packages/docker/api/client.py", line 265, in _raise_for_status
    response.raise_for_status()
  File "/home/airflow/.local/lib/python3.12/site-packages/requests/models.py", line 1021, in raise_for_status
    raise HTTPError(http_error_msg, response=self)
requests.exceptions.HTTPError: 400 Client Error: Bad Request for url: http+docker://localhost/v1.43/containers/create

The above exception was the direct cause of the following exception:

Traceback (most recent call last):
  File "/home/airflow/.local/lib/python3.12/site-packages/airflow/providers/docker/operators/docker.py", line 364, in _run_image
    return self._run_image_with_mounts([*self.mounts, tmp_mount], add_tmp_variable=True)
           ^^^^^^^^^^^^^^^^^^^^^^^^^^^^^^^^^^^^^^^^^^^^^^^^^^^^^^^^^^^^^^^^^^^^^^^^^^^^^
  File "/home/airflow/.local/lib/python3.12/site-packages/airflow/providers/docker/operators/docker.py", line 391, in _run_image_with_mounts
    self.container = self.cli.create_container(
                     ^^^^^^^^^^^^^^^^^^^^^^^^^^
  File "/home/airflow/.local/lib/python3.12/site-packages/docker/api/container.py", line 439, in create_container
    return self.create_container_from_config(config, name, platform)
           ^^^^^^^^^^^^^^^^^^^^^^^^^^^^^^^^^^^^^^^^^^^^^^^^^^^^^^^^^
  File "/home/airflow/.local/lib/python3.12/site-packages/docker/api/container.py", line 456, in create_container_from_config
    return self._result(res, True)
           ^^^^^^^^^^^^^^^^^^^^^^^
  File "/home/airflow/.local/lib/python3.12/site-packages/docker/api/client.py", line 271, in _result
    self._raise_for_status(response)
  File "/home/airflow/.local/lib/python3.12/site-packages/docker/api/client.py", line 267, in _raise_for_status
    raise create_api_error_from_http_exception(e) from e
          ^^^^^^^^^^^^^^^^^^^^^^^^^^^^^^^^^^^^^^^
  File "/home/airflow/.local/lib/python3.12/site-packages/docker/errors.py", line 39, in create_api_error_from_http_exception
    raise cls(e, response=response, explanation=explanation) from e
docker.errors.APIError: 400 Client Error for http+docker://localhost/v1.43/containers/create: Bad Request ("invalid mount config for type "bind": bind source path does not exist: /tmp/airflowtmp6ox5svz3")

During handling of the above exception, another exception occurred:

Traceback (most recent call last):
  File "/home/airflow/.local/lib/python3.12/site-packages/airflow/models/taskinstance.py", line 465, in _execute_task
    result = _execute_callable(context=context, **execute_callable_kwargs)
             ^^^^^^^^^^^^^^^^^^^^^^^^^^^^^^^^^^^^^^^^^^^^^^^^^^^^^^^^^^^^^
  File "/home/airflow/.local/lib/python3.12/site-packages/airflow/models/taskinstance.py", line 432, in _execute_callable
    return execute_callable(context=context, **execute_callable_kwargs)
           ^^^^^^^^^^^^^^^^^^^^^^^^^^^^^^^^^^^^^^^^^^^^^^^^^^^^^^^^^^^^
  File "/home/airflow/.local/lib/python3.12/site-packages/airflow/models/baseoperator.py", line 400, in wrapper
    return func(self, *args, **kwargs)
           ^^^^^^^^^^^^^^^^^^^^^^^^^^^
  File "/home/airflow/.local/lib/python3.12/site-packages/airflow/providers/docker/operators/docker.py", line 502, in execute
    return self._run_image()
           ^^^^^^^^^^^^^^^^^
  File "/home/airflow/.local/lib/python3.12/site-packages/airflow/providers/docker/operators/docker.py", line 373, in _run_image
    return self._run_image_with_mounts(self.mounts, add_tmp_variable=False)
           ^^^^^^^^^^^^^^^^^^^^^^^^^^^^^^^^^^^^^^^^^^^^^^^^^^^^^^^^^^^^^^^^
  File "/home/airflow/.local/lib/python3.12/site-packages/airflow/providers/docker/operators/docker.py", line 437, in _run_image_with_mounts
    raise DockerContainerFailedException(f"Docker container failed: {result!r}", logs=log_lines)
airflow.providers.docker.exceptions.DockerContainerFailedException: Docker container failed: {'StatusCode': 2}
[2024-04-24T23:32:32.821+0000] {taskinstance.py:1205} INFO - Marking task as UP_FOR_RETRY. dag_id=spotify_extract_dag, task_id=el_spotify, execution_date=20240424T232909, start_date=20240424T233231, end_date=20240424T233232
[2024-04-24T23:32:32.830+0000] {standard_task_runner.py:110} ERROR - Failed to execute job 38 for task el_spotify (Docker container failed: {'StatusCode': 2}; 194)
[2024-04-24T23:32:32.853+0000] {local_task_job_runner.py:240} INFO - Task exited with return code 1
[2024-04-24T23:32:32.866+0000] {taskinstance.py:3482} INFO - 0 downstream tasks scheduled from follow-on schedule check
[2024-04-24T23:32:32.869+0000] {local_task_job_runner.py:222} INFO - ::endgroup::
