[2024-04-27T18:18:52.868+0000] {local_task_job_runner.py:120} INFO - ::group::Pre task execution logs
[2024-04-27T18:18:52.886+0000] {taskinstance.py:2073} INFO - Dependencies all met for dep_context=non-requeueable deps ti=<TaskInstance: spotify_extract_dag.el_spotify manual__2024-04-27T18:13:40.687152+00:00 [queued]>
[2024-04-27T18:18:52.891+0000] {taskinstance.py:2073} INFO - Dependencies all met for dep_context=requeueable deps ti=<TaskInstance: spotify_extract_dag.el_spotify manual__2024-04-27T18:13:40.687152+00:00 [queued]>
[2024-04-27T18:18:52.891+0000] {taskinstance.py:2303} INFO - Starting attempt 2 of 3
[2024-04-27T18:18:52.900+0000] {taskinstance.py:2327} INFO - Executing <Task(DockerOperator): el_spotify> on 2024-04-27 18:13:40.687152+00:00
[2024-04-27T18:18:52.905+0000] {warnings.py:110} WARNING - /home/***/.local/lib/python3.12/site-packages/***/task/task_runner/standard_task_runner.py:61: DeprecationWarning: This process (pid=142) is multi-threaded, use of fork() may lead to deadlocks in the child.
  pid = os.fork()

[2024-04-27T18:18:52.906+0000] {standard_task_runner.py:63} INFO - Started process 143 to run task
[2024-04-27T18:18:52.906+0000] {standard_task_runner.py:90} INFO - Running: ['***', 'tasks', 'run', 'spotify_extract_dag', 'el_spotify', 'manual__2024-04-27T18:13:40.687152+00:00', '--job-id', '139', '--raw', '--subdir', 'DAGS_FOLDER/meltano_spotify_dag.py', '--cfg-path', '/tmp/tmpvoigxbiw']
[2024-04-27T18:18:52.908+0000] {standard_task_runner.py:91} INFO - Job 139: Subtask el_spotify
[2024-04-27T18:18:52.939+0000] {task_command.py:426} INFO - Running <TaskInstance: spotify_extract_dag.el_spotify manual__2024-04-27T18:13:40.687152+00:00 [running]> on host c98a6e68ea8f
[2024-04-27T18:18:53.003+0000] {taskinstance.py:2644} INFO - Exporting env vars: AIRFLOW_CTX_DAG_OWNER='***' AIRFLOW_CTX_DAG_ID='spotify_extract_dag' AIRFLOW_CTX_TASK_ID='el_spotify' AIRFLOW_CTX_EXECUTION_DATE='2024-04-27T18:13:40.687152+00:00' AIRFLOW_CTX_TRY_NUMBER='2' AIRFLOW_CTX_DAG_RUN_ID='manual__2024-04-27T18:13:40.687152+00:00'
[2024-04-27T18:18:53.004+0000] {taskinstance.py:430} INFO - ::endgroup::
[2024-04-27T18:18:53.023+0000] {docker.py:359} INFO - Starting docker container from image meltano
[2024-04-27T18:18:53.025+0000] {docker.py:367} WARNING - Using remote engine or docker-in-docker and mounting temporary volume from host is not supported. Falling back to `mount_tmp_dir=False` mode. You can set `mount_tmp_dir` parameter to False to disable mounting and remove the warning
[2024-04-27T18:18:53.902+0000] {docker.py:429} INFO - [2m2024-04-27T18:18:53.901484Z[0m [[32m[1minfo     [0m] [1mThe default environment 'dev' will be ignored for `meltano config`. To configure a specific environment, please use the option `--environment=<environment name>`.[0m
[2024-04-27T18:18:54.018+0000] {docker.py:429} INFO - Extractor 'tap-spotify' setting 'client_id' was set in `.env`: (redacted)
[2024-04-27T18:18:56.193+0000] {docker.py:429} INFO - [2m2024-04-27T18:18:56.192435Z[0m [[32m[1minfo     [0m] [1mThe default environment 'dev' will be ignored for `meltano config`. To configure a specific environment, please use the option `--environment=<environment name>`.[0m
[2024-04-27T18:18:56.307+0000] {docker.py:429} INFO - Extractor 'tap-spotify' setting 'client_secret' was set in `.env`: (redacted)
[2024-04-27T18:18:58.330+0000] {docker.py:429} INFO - [2m2024-04-27T18:18:58.329875Z[0m [[32m[1minfo     [0m] [1mThe default environment 'dev' will be ignored for `meltano config`. To configure a specific environment, please use the option `--environment=<environment name>`.[0m
[2024-04-27T18:18:58.456+0000] {docker.py:429} INFO - Extractor 'tap-spotify' setting 'refresh_token' was set in `.env`: (redacted)
[2024-04-27T18:19:00.518+0000] {docker.py:429} INFO - [2m2024-04-27T18:19:00.518670Z[0m [[32m[1minfo     [0m] [1mThe default environment 'dev' will be ignored for `meltano config`. To configure a specific environment, please use the option `--environment=<environment name>`.[0m
[2024-04-27T18:19:00.656+0000] {docker.py:429} INFO - /venv/lib/python3.10/site-packages/meltano/cli/interactive/config.py:400: RuntimeWarning: Unknown setting ''
  value, metadata = settings.set_with_metadata(
Need help fixing this problem? Visit http://melta.no/ for troubleshooting steps, or to
join our friendly Slack community.

not enough values to unpack (expected at least 1, got 0)
[2024-04-27T18:19:01.977+0000] {taskinstance.py:441} INFO - ::group::Post task execution logs
[2024-04-27T18:19:01.985+0000] {taskinstance.py:2890} ERROR - Task failed with exception
Traceback (most recent call last):
  File "/home/airflow/.local/lib/python3.12/site-packages/docker/api/client.py", line 265, in _raise_for_status
    response.raise_for_status()
  File "/home/airflow/.local/lib/python3.12/site-packages/requests/models.py", line 1021, in raise_for_status
    raise HTTPError(http_error_msg, response=self)
requests.exceptions.HTTPError: 400 Client Error: Bad Request for url: http+docker://localhost/v1.43/containers/create

The above exception was the direct cause of the following exception:

Traceback (most recent call last):
  File "/home/airflow/.local/lib/python3.12/site-packages/airflow/providers/docker/operators/docker.py", line 364, in _run_image
    return self._run_image_with_mounts([*self.mounts, tmp_mount], add_tmp_variable=True)
           ^^^^^^^^^^^^^^^^^^^^^^^^^^^^^^^^^^^^^^^^^^^^^^^^^^^^^^^^^^^^^^^^^^^^^^^^^^^^^
  File "/home/airflow/.local/lib/python3.12/site-packages/airflow/providers/docker/operators/docker.py", line 391, in _run_image_with_mounts
    self.container = self.cli.create_container(
                     ^^^^^^^^^^^^^^^^^^^^^^^^^^
  File "/home/airflow/.local/lib/python3.12/site-packages/docker/api/container.py", line 439, in create_container
    return self.create_container_from_config(config, name, platform)
           ^^^^^^^^^^^^^^^^^^^^^^^^^^^^^^^^^^^^^^^^^^^^^^^^^^^^^^^^^
  File "/home/airflow/.local/lib/python3.12/site-packages/docker/api/container.py", line 456, in create_container_from_config
    return self._result(res, True)
           ^^^^^^^^^^^^^^^^^^^^^^^
  File "/home/airflow/.local/lib/python3.12/site-packages/docker/api/client.py", line 271, in _result
    self._raise_for_status(response)
  File "/home/airflow/.local/lib/python3.12/site-packages/docker/api/client.py", line 267, in _raise_for_status
    raise create_api_error_from_http_exception(e) from e
          ^^^^^^^^^^^^^^^^^^^^^^^^^^^^^^^^^^^^^^^
  File "/home/airflow/.local/lib/python3.12/site-packages/docker/errors.py", line 39, in create_api_error_from_http_exception
    raise cls(e, response=response, explanation=explanation) from e
docker.errors.APIError: 400 Client Error for http+docker://localhost/v1.43/containers/create: Bad Request ("invalid mount config for type "bind": bind source path does not exist: /tmp/airflowtmpayc6jhq8")

During handling of the above exception, another exception occurred:

Traceback (most recent call last):
  File "/home/airflow/.local/lib/python3.12/site-packages/airflow/models/taskinstance.py", line 465, in _execute_task
    result = _execute_callable(context=context, **execute_callable_kwargs)
             ^^^^^^^^^^^^^^^^^^^^^^^^^^^^^^^^^^^^^^^^^^^^^^^^^^^^^^^^^^^^^
  File "/home/airflow/.local/lib/python3.12/site-packages/airflow/models/taskinstance.py", line 432, in _execute_callable
    return execute_callable(context=context, **execute_callable_kwargs)
           ^^^^^^^^^^^^^^^^^^^^^^^^^^^^^^^^^^^^^^^^^^^^^^^^^^^^^^^^^^^^
  File "/home/airflow/.local/lib/python3.12/site-packages/airflow/models/baseoperator.py", line 400, in wrapper
    return func(self, *args, **kwargs)
           ^^^^^^^^^^^^^^^^^^^^^^^^^^^
  File "/home/airflow/.local/lib/python3.12/site-packages/airflow/providers/docker/operators/docker.py", line 502, in execute
    return self._run_image()
           ^^^^^^^^^^^^^^^^^
  File "/home/airflow/.local/lib/python3.12/site-packages/airflow/providers/docker/operators/docker.py", line 373, in _run_image
    return self._run_image_with_mounts(self.mounts, add_tmp_variable=False)
           ^^^^^^^^^^^^^^^^^^^^^^^^^^^^^^^^^^^^^^^^^^^^^^^^^^^^^^^^^^^^^^^^
  File "/home/airflow/.local/lib/python3.12/site-packages/airflow/providers/docker/operators/docker.py", line 437, in _run_image_with_mounts
    raise DockerContainerFailedException(f"Docker container failed: {result!r}", logs=log_lines)
airflow.providers.docker.exceptions.DockerContainerFailedException: Docker container failed: {'StatusCode': 1}
[2024-04-27T18:19:01.988+0000] {taskinstance.py:1205} INFO - Marking task as UP_FOR_RETRY. dag_id=spotify_extract_dag, task_id=el_spotify, execution_date=20240427T181340, start_date=20240427T181852, end_date=20240427T181901
[2024-04-27T18:19:02.001+0000] {standard_task_runner.py:110} ERROR - Failed to execute job 139 for task el_spotify (Docker container failed: {'StatusCode': 1}; 143)
[2024-04-27T18:19:02.025+0000] {local_task_job_runner.py:240} INFO - Task exited with return code 1
[2024-04-27T18:19:02.038+0000] {taskinstance.py:3482} INFO - 0 downstream tasks scheduled from follow-on schedule check
[2024-04-27T18:19:02.039+0000] {local_task_job_runner.py:222} INFO - ::endgroup::
