[2024-04-23 19:49:21,335] {taskinstance.py:877} INFO - Dependencies all met for <TaskInstance: spotify_extract_dag.el_spotify 2024-04-22T00:00:00+00:00 [queued]>
[2024-04-23 19:49:21,344] {taskinstance.py:877} INFO - Dependencies all met for <TaskInstance: spotify_extract_dag.el_spotify 2024-04-22T00:00:00+00:00 [queued]>
[2024-04-23 19:49:21,344] {taskinstance.py:1068} INFO - 
--------------------------------------------------------------------------------
[2024-04-23 19:49:21,344] {taskinstance.py:1069} INFO - Starting attempt 1 of 3
[2024-04-23 19:49:21,344] {taskinstance.py:1070} INFO - 
--------------------------------------------------------------------------------
[2024-04-23 19:49:21,349] {taskinstance.py:1089} INFO - Executing <Task(DockerOperator): el_spotify> on 2024-04-22T00:00:00+00:00
[2024-04-23 19:49:21,354] {standard_task_runner.py:52} INFO - Started process 57 to run task
[2024-04-23 19:49:21,356] {standard_task_runner.py:76} INFO - Running: ['airflow', 'tasks', 'run', 'spotify_extract_dag', 'el_spotify', '2024-04-22T00:00:00+00:00', '--job-id', '5', '--pool', 'meltano_pool', '--raw', '--subdir', 'DAGS_FOLDER/meltano_spotify_dag.py', '--cfg-path', '/tmp/tmpuu_lxiia', '--error-file', '/tmp/tmp17wj927s']
[2024-04-23 19:49:21,356] {standard_task_runner.py:77} INFO - Job 5: Subtask el_spotify
[2024-04-23 19:49:21,382] {logging_mixin.py:104} INFO - Running <TaskInstance: spotify_extract_dag.el_spotify 2024-04-22T00:00:00+00:00 [running]> on host da29c4a4d330
[2024-04-23 19:49:21,410] {taskinstance.py:1283} INFO - Exporting the following env vars:
AIRFLOW_CTX_DAG_OWNER=airflow
AIRFLOW_CTX_DAG_ID=spotify_extract_dag
AIRFLOW_CTX_TASK_ID=el_spotify
AIRFLOW_CTX_EXECUTION_DATE=2024-04-22T00:00:00+00:00
AIRFLOW_CTX_DAG_RUN_ID=scheduled__2024-04-22T00:00:00+00:00
[2024-04-23 19:49:21,415] {taskinstance.py:1482} ERROR - Task failed with exception
Traceback (most recent call last):
  File "/home/airflow/.local/lib/python3.6/site-packages/urllib3/connectionpool.py", line 677, in urlopen
    chunked=chunked,
  File "/home/airflow/.local/lib/python3.6/site-packages/urllib3/connectionpool.py", line 392, in _make_request
    conn.request(method, url, **httplib_request_kw)
  File "/usr/local/lib/python3.6/http/client.py", line 1291, in request
    self._send_request(method, url, body, headers, encode_chunked)
  File "/usr/local/lib/python3.6/http/client.py", line 1337, in _send_request
    self.endheaders(body, encode_chunked=encode_chunked)
  File "/usr/local/lib/python3.6/http/client.py", line 1286, in endheaders
    self._send_output(message_body, encode_chunked=encode_chunked)
  File "/usr/local/lib/python3.6/http/client.py", line 1046, in _send_output
    self.send(msg)
  File "/usr/local/lib/python3.6/http/client.py", line 984, in send
    self.connect()
  File "/home/airflow/.local/lib/python3.6/site-packages/docker/transport/unixconn.py", line 43, in connect
    sock.connect(self.unix_socket)
FileNotFoundError: [Errno 2] No such file or directory

During handling of the above exception, another exception occurred:

Traceback (most recent call last):
  File "/home/airflow/.local/lib/python3.6/site-packages/requests/adapters.py", line 449, in send
    timeout=timeout
  File "/home/airflow/.local/lib/python3.6/site-packages/urllib3/connectionpool.py", line 727, in urlopen
    method, url, error=e, _pool=self, _stacktrace=sys.exc_info()[2]
  File "/home/airflow/.local/lib/python3.6/site-packages/urllib3/util/retry.py", line 410, in increment
    raise six.reraise(type(error), error, _stacktrace)
  File "/home/airflow/.local/lib/python3.6/site-packages/urllib3/packages/six.py", line 734, in reraise
    raise value.with_traceback(tb)
  File "/home/airflow/.local/lib/python3.6/site-packages/urllib3/connectionpool.py", line 677, in urlopen
    chunked=chunked,
  File "/home/airflow/.local/lib/python3.6/site-packages/urllib3/connectionpool.py", line 392, in _make_request
    conn.request(method, url, **httplib_request_kw)
  File "/usr/local/lib/python3.6/http/client.py", line 1291, in request
    self._send_request(method, url, body, headers, encode_chunked)
  File "/usr/local/lib/python3.6/http/client.py", line 1337, in _send_request
    self.endheaders(body, encode_chunked=encode_chunked)
  File "/usr/local/lib/python3.6/http/client.py", line 1286, in endheaders
    self._send_output(message_body, encode_chunked=encode_chunked)
  File "/usr/local/lib/python3.6/http/client.py", line 1046, in _send_output
    self.send(msg)
  File "/usr/local/lib/python3.6/http/client.py", line 984, in send
    self.connect()
  File "/home/airflow/.local/lib/python3.6/site-packages/docker/transport/unixconn.py", line 43, in connect
    sock.connect(self.unix_socket)
urllib3.exceptions.ProtocolError: ('Connection aborted.', FileNotFoundError(2, 'No such file or directory'))

During handling of the above exception, another exception occurred:

Traceback (most recent call last):
  File "/home/airflow/.local/lib/python3.6/site-packages/airflow/models/taskinstance.py", line 1138, in _run_raw_task
    self._prepare_and_execute_task_with_callbacks(context, task)
  File "/home/airflow/.local/lib/python3.6/site-packages/airflow/models/taskinstance.py", line 1311, in _prepare_and_execute_task_with_callbacks
    result = self._execute_task(context, task_copy)
  File "/home/airflow/.local/lib/python3.6/site-packages/airflow/models/taskinstance.py", line 1341, in _execute_task
    result = task_copy.execute(context=context)
  File "/home/airflow/.local/lib/python3.6/site-packages/airflow/providers/docker/operators/docker.py", line 293, in execute
    if self.force_pull or not self.cli.images(name=self.image):
  File "/home/airflow/.local/lib/python3.6/site-packages/docker/api/image.py", line 89, in images
    res = self._result(self._get(self._url("/images/json"), params=params),
  File "/home/airflow/.local/lib/python3.6/site-packages/docker/utils/decorators.py", line 46, in inner
    return f(self, *args, **kwargs)
  File "/home/airflow/.local/lib/python3.6/site-packages/docker/api/client.py", line 230, in _get
    return self.get(url, **self._set_request_timeout(kwargs))
  File "/home/airflow/.local/lib/python3.6/site-packages/requests/sessions.py", line 555, in get
    return self.request('GET', url, **kwargs)
  File "/home/airflow/.local/lib/python3.6/site-packages/requests/sessions.py", line 542, in request
    resp = self.send(prep, **send_kwargs)
  File "/home/airflow/.local/lib/python3.6/site-packages/requests/sessions.py", line 655, in send
    r = adapter.send(request, **kwargs)
  File "/home/airflow/.local/lib/python3.6/site-packages/requests/adapters.py", line 498, in send
    raise ConnectionError(err, request=request)
requests.exceptions.ConnectionError: ('Connection aborted.', FileNotFoundError(2, 'No such file or directory'))
[2024-04-23 19:49:21,418] {taskinstance.py:1532} INFO - Marking task as UP_FOR_RETRY. dag_id=spotify_extract_dag, task_id=el_spotify, execution_date=20240422T000000, start_date=20240423T194921, end_date=20240423T194921
[2024-04-23 19:49:21,448] {local_task_job.py:146} INFO - Task exited with return code 1
